<?xml version="1.0" ?>
<!-- =================================================================================== -->
<!-- |    This document was autogenerated by xacro from /home/nhantastrew/Workspaces/sawyer_ws/src/sawyer_robot/sawyer_description/urdf/sawyer_electric_gripper.urdf.xacro | -->
<!-- |    EDITING THIS FILE BY HAND IS NOT RECOMMENDED                                 | -->
<!-- =================================================================================== -->
<robot name="end_effector">
  <!-- Base of whole end effector - (Connector Plate + Electric Gripper + Fingers + Tips) -->
  <link name="right_gripper_base">
    <inertial>
      <!-- Sum Gripper Mass - for whole end effector, measured from end of plastic cuff -->
      <mass value="0.47"/>
      <origin rpy="0 0 0" xyz="0.0028 -0.0004 0.0343"/>
      <inertia ixx="1e-08" ixy="0" ixz="0" iyy="1e-08" iyz="0" izz="1e-08"/>
    </inertial>
  </link>
  <!-- Electric Gripper Base Link -->
  <link name="right_electric_gripper_base">
    <visual>
      <origin rpy="0 0 0" xyz="0 0 0"/>
      <geometry>
        <mesh filename="package://intera_tools_description/meshes/electric_gripper/electric_gripper_base.DAE"/>
      </geometry>
    </visual>
    <collision>
      <origin rpy="-1.5707963267948966 3.141592653589793 0" xyz="0.004 0.0 0.025"/>
      <geometry>
        <cylinder length="0.1" radius="0.029"/>
      </geometry>
      <material name="darkred">
        <color rgba=".5 .1 .1 1"/>
      </material>
    </collision>
    <inertial>
      <origin rpy="-1.5707963267948966 3.141592653589793 0" xyz="0.0 0.0 0.0"/>
      <mass value="2e-06"/>
      <inertia ixx="1.1e-09" ixy="0" ixz="0" iyy="1.1e-09" iyz="0" izz="1.1e-09"/>
    </inertial>
  </link>
  <!-- Connector Plate Joint -->
  <joint name="right_connector_plate_base_joint" type="fixed">
    <origin rpy="0 0 0" xyz="0 0 0.0018"/>
    <parent link="right_gripper_base"/>
    <child link="right_connector_plate_base"/>
  </joint>
  <link name="right_connector_plate_base">
    <inertial>
      <origin rpy="0 0 0" xyz="0 0 0"/>
      <mass value="0.0"/>
      <inertia ixx="6.9922E-05" ixy="6.1026E-08" ixz="-1.7042E-06" iyy="6.8188E-05" iyz="-1.6118E-08" izz="0.00012392"/>
    </inertial>
    <visual>
      <origin rpy="0 0 0" xyz="0 0 0"/>
      <geometry>
        <mesh filename="package://intera_tools_description/meshes/connector_plate/connector_plate.STL"/>
      </geometry>
      <material name="black">
        <color rgba="0.05 0.05 0.05 1"/>
      </material>
    </visual>
    <collision>
      <origin rpy="0 0 0" xyz="0 0 0.0135"/>
      <geometry>
        <cylinder length="0.0302" radius="0.04"/>
      </geometry>
      <material name="darkred">
        <color rgba=".5 .1 .1 1"/>
      </material>
    </collision>
  </link>
  <link name="right_connector_plate_mount"/>
  <joint name="right_connector_plate_mount_joint" type="fixed">
    <origin rpy="0 0 0" xyz="0 0 0.0176"/>
    <parent link="right_connector_plate_base"/>
    <child link="right_connector_plate_mount"/>
  </joint>
  <!-- Electric Gripper Base joint -->
  <joint name="right_electric_gripper_base_joint" type="fixed">
    <origin rpy="0 0 0" xyz="0 0 0"/>
    <parent link="right_connector_plate_mount"/>
    <child link="right_electric_gripper_base"/>
  </joint>
  <link name="right_gripper_l_finger">
    <visual>
      <origin rpy="0 0 -3.141592653589793" xyz="0 0 0"/>
      <geometry>
        <mesh filename="package://intera_tools_description/meshes/electric_gripper/fingers/standard_narrow.DAE"/>
      </geometry>
    </visual>
    <collision>
      <origin rpy="0 0 -3.141592653589793" xyz="0 0.01725 0.04"/>
      <geometry>
        <box size="0.01 0.0135 0.075"/>
      </geometry>
    </collision>
    <collision>
      <origin rpy="0 0 -3.141592653589793" xyz="-0.005 -0.003 0.0083"/>
      <geometry>
        <box size="0.01 0.05 0.017"/>
      </geometry>
    </collision>
    <inertial>
      <origin rpy="0 0 -3.141592653589793" xyz="0 0 0"/>
      <mass value="0.001"/>
      <inertia ixx="0.01" ixy="0" ixz="0" iyy="0.01" iyz="0" izz="0.01"/>
    </inertial>
  </link>
  <link name="right_gripper_l_finger_tip">
    <visual>
      <origin rpy="0 0 3.141592653589793" xyz="0 0 0"/>
      <geometry>
        <mesh filename="package://intera_tools_description/meshes/electric_gripper/fingers/basic_soft_tip.DAE"/>
      </geometry>
    </visual>
    <collision>
      <origin rpy="0 0 3.141592653589793" xyz="0 -0.0045 -0.015"/>
      <geometry>
        <box size="0.016 0.007 0.037"/>
      </geometry>
    </collision>
    <inertial>
      <origin rpy="0 0 3.141592653589793" xyz="0 0 0"/>
      <mass value="0.001"/>
      <inertia ixx="0.01" ixy="0" ixz="0" iyy="0.01" iyz="0" izz="0.01"/>
    </inertial>
  </link>
  <joint name="right_gripper_l_finger_tip_joint" type="fixed">
    <origin rpy="0 0 0" xyz="0.0 0.01725 0.075"/>
    <parent link="right_gripper_l_finger"/>
    <child link="right_gripper_l_finger_tip"/>
  </joint>
  <link name="right_gripper_r_finger">
    <visual>
      <origin rpy="0 0 -0.0" xyz="0 0 0"/>
      <geometry>
        <mesh filename="package://intera_tools_description/meshes/electric_gripper/fingers/standard_narrow.DAE"/>
      </geometry>
    </visual>
    <collision>
      <origin rpy="0 0 -0.0" xyz="0 -0.01725 0.04"/>
      <geometry>
        <box size="0.01 0.0135 0.075"/>
      </geometry>
    </collision>
    <collision>
      <origin rpy="0 0 -0.0" xyz="0.005 0.003 0.0083"/>
      <geometry>
        <box size="0.01 0.05 0.017"/>
      </geometry>
    </collision>
    <inertial>
      <origin rpy="0 0 -0.0" xyz="0 0 0"/>
      <mass value="0.001"/>
      <inertia ixx="0.01" ixy="0" ixz="0" iyy="0.01" iyz="0" izz="0.01"/>
    </inertial>
  </link>
  <link name="right_gripper_r_finger_tip">
    <visual>
      <origin rpy="0 0 0.0" xyz="0 0 0"/>
      <geometry>
        <mesh filename="package://intera_tools_description/meshes/electric_gripper/fingers/basic_soft_tip.DAE"/>
      </geometry>
    </visual>
    <collision>
      <origin rpy="0 0 0.0" xyz="0 0.0045 -0.015"/>
      <geometry>
        <box size="0.016 0.007 0.037"/>
      </geometry>
    </collision>
    <inertial>
      <origin rpy="0 0 0.0" xyz="0 0 0"/>
      <mass value="0.001"/>
      <inertia ixx="0.01" ixy="0" ixz="0" iyy="0.01" iyz="0" izz="0.01"/>
    </inertial>
  </link>
  <joint name="right_gripper_r_finger_tip_joint" type="fixed">
    <origin rpy="0 0 0" xyz="0.0 -0.01725 0.075"/>
    <parent link="right_gripper_r_finger"/>
    <child link="right_gripper_r_finger_tip"/>
  </joint>
  <joint name="right_gripper_base_joint" type="fixed">
    <origin rpy="0 0 0" xyz="0 0 -0.005"/>
    <parent link="right_hand"/>
    <child link="right_gripper_base"/>
  </joint>
  <joint name="right_gripper_tip_joint" type="fixed">
    <origin rpy="0 0 0" xyz="0 0 0.14062"/>
    <parent link="right_gripper_base"/>
    <child link="right_gripper_tip"/>
  </joint>
  <!-- Electric Gripper Tip link -->
  <link name="right_gripper_tip">
    <inertial>
      <origin rpy="0 0 0" xyz="0 0 0"/>
      <mass value="2e-06"/>
      <inertia ixx="1.1e-09" ixy="0" ixz="0" iyy="1.1e-09" iyz="0" izz="1.1e-09"/>
    </inertial>
  </link>
  <joint name="right_gripper_l_finger_joint" type="prismatic">
    <origin rpy="0 0 0" xyz="0.003 -0.0014999999999999996 0.04552"/>
    <axis xyz="0 1 0"/>
    <parent link="right_electric_gripper_base"/>
    <child link="right_gripper_l_finger"/>
    <limit effort="20.0" lower="0.0" upper="0.020833" velocity="5.0"/>
    <dynamics damping="100.0" friction="500.0"/>
  </joint>
  <joint name="right_gripper_r_finger_joint" type="prismatic">
    <origin rpy="0 0 0" xyz="0.003 0.0014999999999999996 0.04552"/>
    <axis xyz="0 1 0"/>
    <parent link="right_electric_gripper_base"/>
    <child link="right_gripper_r_finger"/>
    <limit effort="20.0" lower="-0.020833" upper="0.0" velocity="5.0"/>
    <mimic joint="right_gripper_l_finger_joint" multiplier="-1.0"/>
    <dynamics damping="100.0" friction="500.0"/>
  </joint>
</robot>
